Workbook

Sheet iNaturalist_Experts_US_Canada
A1: Name | B1: iNaturalist_username | C1: iNaturalist_name | D1: iNaturalist_id | E1: NatureServe Network Staff Status | F1: Organization | G1: Title | H1: Taxonomic Expertise | I1: Expertise LU | J1: Comments on Taxonomic Expertise | K1: Region of Expertise | L1: Source (past efforts or name and email) | M1: No_Observations | N1: No_Identifications | O1: No_Species | P1: Curator
A2: Alexandre Anctil | B2: a_anctil | D2: 1381960 | E2: No | F2: Quebec CDC | G2: Coordonnator - fauna component | H2: Vertebrates|Birds | I2: A% | K2: NB, NS, PE | L2: Canadian Node Expert List | M2: 18289 | N2: 24311 | O2: 2030
A3: Andrea Benville | B3: a_b | C3: Andrea Benville | D3: 35013 | E3: Current | F3: Saskatchewan Conservation Data Centre | L3: 2020 network survey on iNaturalist | M3: 845 | N3: 870 | O3: 471
A4: Alison Smith | B4: a_smith | C4: Alison Smith | D4: 1340454 | E4: Current | F4: Ontario Natural Heritage Information Centre | G4: Natural Heritage Zoologist | L4: NatureServe Network Staff List | M4: 7213 | N4: 5416 | O4: 1941
A5: Aaron Liston | B5: aaronliston | C5: Aaron Liston | D5: 266181 | E5: No | H5: Vascular Plants, particularly Astragalus | I5: P% | L5: MTNHP Expert List | M5: 3907 | N5: 48819 | O5: 2107 | P5: curator
A6: Aaron Marcus | B6: aaronmarcus | C6: Aaron Marcus | D6: 682499 | E6: Former | H6: Vascular|Non-vascular Plants | I6: P%|NB% | L6: NatureServe Network Staff List | M6: 281 | N6: 60 | O6: 168
A7: Ben Rostron | B7: ab_orchid | D7: 3304841 | E7: No | F7: University of Alberta | G7: Emeritus Professor | H7: Orchidaceae | I7: PMORC% | K7: AB | L7: Canadian Node Expert List and MTNHP Expert List | M7: 399 | N7: 35462 | O7: 30
A8: Robin Abernethy | B8: aber_r16 | C8: Robin Abernethy | D8: 2528838 | E8: Current | F8: Northwest Territories Conservation Data Centre | G8: GIS and Wildlife Data Specialist | L8: NatureServe Network Staff List | M8: 110 | N8: 0 | O8: 82
A9: Andrew Smith | B9: abtsmith | C9: Andrew Smith | D9: 1327158 | E9: No | F9: Canadian Museum of Nature and the University of Nebraska State Museum. | G9: Research Associate | H9: Insects|Coleoptera | I9: II% | J9: Especially Scarabidae | L9: MBP Expert List | M9: 59 | N9: 13981 | O9: 48 | P9: curator
A10: Andrew Christensen | B10: achr2 | C10: Andrew Christensen | D10: 7072130 | E10: Current | F10: Oregon Biodiversity Information Center | G10: Watershed GIS Analyst | H10: Vascular Plants | I10: P% | L10: 2024 Network Survey | M10: 0 | N10: 0 | O10: 0
A11: Amanda Veinotte | B11: acveinotte | C11: Amanda Veinotte | D11: 1122139 | E11: Current | F11: Massachusetts Natural Heritage & Endangered Species Program | G11: Program Coordinator | L11: NatureServe Network Staff List | M11: 98 | N11: 2 | O11: 79
A12: Adam Durocher | B12: adamdurocher | D12: 1387541 | E12: Current | F12: Atlantic Canada Conservation Data Centre | G12: Newfoundland and Labrador Data Manager | L12: NatureServe Network Staff List | M12: 290 | N12: 7 | O12: 210
A13: Alex Dohman | B13: adohman | C13: Alex Dohman | D13: 1297292 | E13: Current | F13: North Dakota Natural Heritage Inventory | G13: Biologist | L13: NatureServe Network Staff List | M13: 136 | N13: 88 | O13: 115
A14: Adam Martin | B14: ady_m | C14: Adam Martin | D14: 11864 | E14: No | F14: Ecostudies Institute | G14: Botanist and Applied Ecologist | H14: Vascular Plants|Mammals | I14: P%|AM% | J14: Ecostudies Institute, Washington | L14: 2024 Network Survey | M14: 1047 | N14: 266 | O14: 441
A15: Ansel Fiddaman | B15: afid | D15: 1254600 | E15: No | H15: Orchidaceae | I15: PMORC% | K15: NF/LB | L15: Canadian Node Expert List and MTNHP Expert List | M15: 3071 | N15: 65876 | O15: 62
A16: Alain Belliveau | B16: agbelliveau | D16: 533332 | E16: No | F16: E.C. Smith Herbarium, Acadia University | G16: Collections Manager | H16: Vascular Plants|Lichens | I16: P%|NL% | K16: YT, NB, NS, PE | L16: Canadian Node Expert List | M16: 1211 | N16: 1495 | O16: 730
A17: Andrew Grosse | B17: agrosse | D17: 3596662 | E17: Current | F17: South Carolina Department of Natural Resources | G17: State Herpetologist | H17: Amphibia|Reptilia | I17: AA%|AR% | J17: SC DNR Herpetologist, 20 years experience, South Carolina | L17: 2024 Network Survey | M17: 0 | N17: 0 | O17: 0
A18: Alejandro Huereca Delgado | B18: ahuereca | C18: Alejandro Huereca Delgado | D18: 683372 | E18: No | F18: University of Alberta | G18: Master's Degree Student huerecad@ualberta.ca | H18: Lichens and Lichenicolous Fungi | I18: NL% | K18: Mostly Mexico | L18: Denny Bohmer; umbohmer@gmail.com | M18: 6002 | N18: 17343 | O18: 2273 | P18: curator
A19: Arturo Santos | B19: aispinsects | C19: Arturo Santos | D19: 604948 | E19: No | H19: Diptera, particularly Anthomyiidae|Orthoptera | I19: IIDIP%|IIORT% | J19: Primary expertise with insects of central Florida peninsula and New York. | L19: 2024 Network Survey | M19: 4173 | N19: 50188 | O19: 1955 | P19: curator
A20: Amy Jewitt | B20: ajewitt | C20: Amy Jewitt | D20: 16288 | E20: Current | F20: Pennsylvania Natural Heritage Program | G20: Invasive Species Coordinator | H20: Invasive species | I20: P%|A%|I% | L20: NatureServe Network Staff List | M20: 92 | N20: 13 | O20: 66
A21: Allan Trently | B21: ajtrently | C21: Trently,Allan J | D21: 29618 | E21: Current | F21: Tennessee Division of Natural Areas | G21: Stewardship Ecologist (West TN) | L21: NatureServe Network Staff List | M21: 4723 | N21: 473 | O21: 2271
A22: Alex Wright | B22: ajwright | C22: Alex Wright | D22: 205278 | E22: No | F22: Bellevue Botanical Garden | G22: Curator | H22: Vascular Plants | I22: P% | K22: NB, NS, PE | L22: MTNHP Expert List and Canadian Node Expert List | M22: 4418 | N22: 201700 | O22: 1477 | P22: curator
A23: Alec Kaisand | B23: akaisand | C23: Alec Kaisand | D23: 1067639 | E23: Current | F23: Massachusetts Natural Heritage & Endangered Species Program | G23: NHESP GIS Manager | L23: NatureServe Network Staff List | M23: 12 | N23: 0 | O23: 10
A24: Alan Rockefeller | B24: alan_rockefeller | C24: Alan Rockefeller | D24: 25945 | E24: No | H24: Fungi | I24: NF%|NL% | L24: MTNHP and MBP Expert List | M24: 28884 | N24: 300239 | O24: 6529 | P24: curator
A25: Alan Liang | B25: alanliang | C25: Alan Liang | D25: 2650187 | E25: No | H25: Lepidoptera | I25: IILE% | L25: MTNHP Expert List | M25: 1259 | N25: 124712 | O25: 105
A26: Dirk C. Albach | B26: albach | D26: 726060 | E26: No | H26: Veronica | I26: PDSCR% | J26: The world's foremost Veronica expert. | L26: MTNHP and MBP Expert List | M26: 1953 | N26: 202824 | O26: 1020 | P26: curator
A27: Alex Abair | B27: alex_abair | C27: Alex Abair | D27: 434305 | E27: No | H27: Lamiaceae (mints) | I27: PDLAM% | J27: Removed flag due to too many cultivated species. | L27: MTNHP and MBP Expert List | M27: 9343 | N27: 203899 | O27: 3331 | P27: curator
A28: Alex Harman | B28: alex_cicindela_guy | C28: Alex Harman | D28: 579740 | E28: No | F28: Santa Barbara Museum of Natural History | G28: Schlinger Chair of Entomology | H28: Coleoptera|Orthoptera|Lepidoptera | I28: IICOL%|IIORT%|IILE% | L28: Canadian Node Expert List; updated expertise on 5/9/25 to account for iNat profile update | M28: 11851 | N28: 233520 | O28: 4519 | P28: curator
A29: Alexandre Bergeron | B29: alexandre_bergeron | C29: Alexandre Bergeron | D29: 4366607 | E29: No | F29: University of Montreal | G29: Botanist | H29: Vascular Plants | I29: P% | K29: NWT | L29: Canadian Node Expert List | M29: 142 | N29: 1402 | O29: 130
A30: Ali Chaney | B30: alichaney | C30: Ali Chaney | D30: 1659821 | E30: Current | F30: Nevada Natural Heritage Program | L30: 2020 network survey on iNaturalist | M30: 39 | N30: 3 | O30: 27
A31: Allison Siemens Worsley | B31: allisonsw_nsc | C31: Allison | D31: 119123 | E31: Current | F31: NatureServe Canada | L31: 2020 network survey on iNaturalist | M31: 144 | N31: 20 | O31: 105 | P31: curator
A32: Al Schotz | B32: alschotz | C32: Al Schotz | D32: 406181 | E32: Current | F32: Alabama Natural Heritage Program | G32: Botanist | L32: NatureServe Network Staff List | M32: 191 | N32: 61 | O32: 179
A33: Alvan Buckley | B33: alvanbuckley | D33: 1513192 | E33: No | H33: General | I33: P%|A%|I% | K33: NF/LB | L33: Canadian Node Expert List | M33: 408 | N33: 538 | O33: 289
A34: Amaad Blades | B34: amaad_blades | D34: 7366982 | E34: Current | F34: Georgia Department of Natural Resources | G34: Wildlife Technician | H34: General | I34: P%|A%|I% | L34: 2024 Network Survey | M34: 244 | N34: 105 | O34: 212
A35: Amber Nguyen | B35: amber42836 | C35: Amber Nguyen | D35: 7443072 | E35: Current | F35: Michigan Natural Features Inventory | G35: Research Assistant | L35: NatureServe Network Staff List | M35: 0 | N35: 0 | O35: 0
A36: Andrew Meeds | B36: ameeds | C36: Andrew Meeds | D36: 917390 | E36: No | H36: Insects | I36: II% | L36: MBP Expert List | M36: 13262 | N36: 91187 | O36: 3770 | P36: curator
A37: Harpo Faust | B37: amen2stamens | C37: Harpo Faust | D37: 14828 | E37: No | F37: University of New Mexico | G37: Herbarium Manager | H37: Plants|Pteridophytes | I37: P% | L37: 2024 Network Survey | M37: 1650 | N37: 41 | O37: 1049
A38: Nathan Jones | B38: americanisopodologist | C38: Nathan T. Jones | D38: 1925317 | E38: No | H38: Isopods | I38: ICMAL% | J38: Currently writing a field guide to isopods of North America (both aquatic and terrestrial). https://www.americanisopodsmyriapods.com/taxonomic-guide-to-isopods-of-north-america | L38: Bryce Maxell bmaxell@mt.gov on 8/9/24. | M38: 15840 | N38: 92461 | O38: 1784 | P38: curator
A39: Amie Enns | B39: amieenns_nsc | C39: Amie Enns | D39: 114023 | E39: Current | F39: NatureServe Canada | G39: National Data Manager | L39: NatureServe Network Staff List | M39: 74 | N39: 696 | O39: 67
A40: Amy Buthod | B40: amybuthod | D40: 221999 | E40: Current | F40: Oklahoma Natural Heritage Inventory | G40: Botanical Specialist | H40: Plants | I40: P%|NB%|NA% | L40: NatureServe Network Staff List | M40: 564 | N40: 39356 | O40: 431
...

Sheet Taxa_Not_Identifiable_w_Photos_
A1: Scientific Name | B1: Common Name | C1: Taxonomic Level | D1: Geographic Area of Revelance | E1: What is required to reliably determine species identification? | F1: Submitter Name | G1: Submitter Email
A2: Neotamias ruficaudus; Neotamias amoenus; Neotamias minimus | B2: Red-tailed chipmunk; Yellow-pine Chipmunk; Least Chipmunk | C2: Neotamias | D2: Mountainous areas of Northern Rockies where species co-occur | E2: Clean skeleton. Occasionally individuals can be identified based on pelage and detailed habitat but this is rare. | F2: Dan Bachen | G2: dbachen@mt.gov

Sheet Summary Statistics
B1: No_Observations | C1: No_Identifications | D1: No_Species | E1: No_Curators
A2: Overall
A3: Total | B3: =SUM(iNaturalist_Experts_US_Canada!M2:M742) -> 4239609 | C3: =SUM(iNaturalist_Experts_US_Canada!N2:N742) -> 29816516
A4: Count > 0 | B4: =COUNTIF(iNaturalist_Experts_US_Canada!M2:M742,">0") -> 678 | C4: =COUNTIF(iNaturalist_Experts_US_Canada!N2:N742,">0") -> 637 | D4: =COUNTIF(iNaturalist_Experts_US_Canada!O2:O742,">0") -> 671 | E4: =COUNTIF(iNaturalist_Experts_US_Canada!P2:P742,"Curator") -> 139
A5: Average | B5: =AVERAGE(iNaturalist_Experts_US_Canada!M2:M742) -> 5776.0341 | C5: =AVERAGE(iNaturalist_Experts_US_Canada!N2:N742) -> 40621.956 | D5: =AVERAGE(iNaturalist_Experts_US_Canada!O2:O742) -> 1109.1131
A7: Other Experts
A8: Total | B8: =SUM(iNaturalist_Experts_US_Canada!M333:M742) -> 2265105 | C8: =SUM(iNaturalist_Experts_US_Canada!N333:N742) -> 17308918
A9: Count > 0 | B9: =COUNTIF(iNaturalist_Experts_US_Canada!M333:M742,">0") -> 371 | C9: =COUNTIF(iNaturalist_Experts_US_Canada!N333:N742,">0") -> 346 | D9: =COUNTIF(iNaturalist_Experts_US_Canada!O333:O742,">0") -> 366 | E9: =COUNTIF(iNaturalist_Experts_US_Canada!P333:P742,"Curator") -> 73
A10: Average | B10: =AVERAGE(iNaturalist_Experts_US_Canada!M333:M742) -> 5579.0764 | C10: =AVERAGE(iNaturalist_Experts_US_Canada!N333:N742) -> 42632.803 | D10: =AVERAGE(iNaturalist_Experts_US_Canada!O333:O742) -> 1050.9434
A12: Current or Former NatureServe Network Staff
A13: Total | B13: =SUM(iNaturalist_Experts_US_Canada!M2:M331) -> 1973892 | C13: =SUM(iNaturalist_Experts_US_Canada!N2:N331) -> 12503573
A14: Count > 0 | B14: =COUNTIF(iNaturalist_Experts_US_Canada!M2:M331,">0") -> 306 | C14: =COUNTIF(iNaturalist_Experts_US_Canada!N2:N331,">0") -> 290 | D14: =COUNTIF(iNaturalist_Experts_US_Canada!O2:O331,">0") -> 304 | E14: =COUNTIF(iNaturalist_Experts_US_Canada!P2:P331,"Curator") -> 66
A15: Average | B15: =AVERAGE(iNaturalist_Experts_US_Canada!M2:M331) -> 6036.367 | C15: =AVERAGE(iNaturalist_Experts_US_Canada!N2:N331) -> 38237.226 | D15: =AVERAGE(iNaturalist_Experts_US_Canada!O2:O331) -> 1183.0612
A17: Count of Experts with Taxonomic Expertise Listed | B17: 460 of 717...so 257 network staff have iNaturalist accounts, but their expertise is not yet listed.
